<?xml version="1.0" ?>
<!-- =================================================================================== -->
<!-- |    This document was autogenerated by xacro from ../xacro/robot.xacro           | -->
<!-- |    EDITING THIS FILE BY HAND IS NOT RECOMMENDED                                 | -->
<!-- =================================================================================== -->
<robot name="go1">
  <material name="black">
    <color rgba="0.0 0.0 0.0 1.0"/>
  </material>
  <material name="blue">
    <color rgba="0.0 0.0 0.8 1.0"/>
  </material>
  <material name="green">
    <color rgba="0.0 0.8 0.0 1.0"/>
  </material>
  <material name="grey">
    <color rgba="0.2 0.2 0.2 1.0"/>
  </material>
  <material name="silver">
    <color rgba="0.9137254901960784 0.9137254901960784 0.8470588235294118 1.0"/>
  </material>
  <material name="orange">
    <color rgba="1.0 0.4235294117647059 0.0392156862745098 1.0"/>
  </material>
  <material name="brown">
    <color rgba="0.8705882352941177 0.8117647058823529 0.7647058823529411 1.0"/>
  </material>
  <material name="red">
    <color rgba="0.8 0.0 0.0 1.0"/>
  </material>
  <material name="white">
    <color rgba="1.0 1.0 1.0 1.0"/>
  </material>
  <!-- ros_control plugin -->
  <gazebo>
    <plugin filename="libgazebo_ros_control.so" name="gazebo_ros_control">
      <robotNamespace>/go1_gazebo</robotNamespace>
      <robotSimType>gazebo_ros_control/DefaultRobotHWSim</robotSimType>
    </plugin>
  </gazebo>
  <!-- Show the trajectory of trunk center. -->
  <gazebo>
    <plugin filename="libLinkPlot3DPlugin.so" name="3dplot">
      <frequency>10</frequency>
      <plot>
        <link>base</link>
        <pose>0 0 0 0 0 0</pose>
        <material>Gazebo/Yellow</material>
      </plot>
    </plugin>
  </gazebo>
  <!-- Apply force plugin -->
  <gazebo>
    <plugin filename="libgazebo_ros_force.so" name="gazebo_ros_force">
      <bodyName>trunk</bodyName>
      <topicName>/apply_force/trunk</topicName>
    </plugin>
  </gazebo>
  <gazebo reference="imu_link">
    <gravity>true</gravity>
    <sensor name="imu_sensor" type="imu">
      <always_on>true</always_on>
      <update_rate>1000</update_rate>
      <visualize>true</visualize>
      <topic>__default_topic__</topic>
      <plugin filename="libgazebo_ros_imu_sensor.so" name="imu_plugin">
        <topicName>trunk_imu</topicName>
        <bodyName>imu_link</bodyName>
        <updateRateHZ>1000.0</updateRateHZ>
        <gaussianNoise>0.0</gaussianNoise>
        <xyzOffset>0 0 0</xyzOffset>
        <rpyOffset>0 0 0</rpyOffset>
        <frameName>imu_link</frameName>
      </plugin>
      <pose>0 0 0 0 0 0</pose>
    </sensor>
  </gazebo>
  <gazebo reference="depthCamera_link_left">
    <sensor name="camera_link_camera" type="depth">
      <update_rate>20</update_rate>
      <camera>
        <horizontal_fov>1.047198</horizontal_fov>
        <image>
          <width>640</width>
          <height>480</height>
          <format>R8G8B8</format>
        </image>
        <clip>
          <near>0.05</near>
          <far>3</far>
        </clip>
      </camera>
      <plugin filename="libgazebo_ros_openni_kinect.so" name="camera_link_controller">
        <baseline>0.2</baseline>
        <alwaysOn>true</alwaysOn>
        <updateRate>1.0</updateRate>
        <cameraName>camera_link_ir</cameraName>
        <imageTopicName>/camera_link_go1/color/image_raw</imageTopicName>
        <cameraInfoTopicName>/camera_link_go1/color/camera_info</cameraInfoTopicName>
        <depthImageTopicName>/camera_link_go1/depth/image_raw</depthImageTopicName>
        <depthImageInfoTopicName>/camera_link_go1/depth/camera_info</depthImageInfoTopicName>
        <pointCloudTopicName>/camera_link_go1/depth/points</pointCloudTopicName>
        <frameName>depthCamera_link_left</frameName>
        <pointCloudCutoff>0.5</pointCloudCutoff>
        <pointCloudCutoffMax>3.0</pointCloudCutoffMax>
        <distortionK1>0.00000001</distortionK1>
        <distortionK2>0.00000001</distortionK2>
        <distortionK3>0.00000001</distortionK3>
        <distortionT1>0.00000001</distortionT1>
        <distortionT2>0.00000001</distortionT2>
        <CxPrime>0</CxPrime>
        <Cx>0</Cx>
        <Cy>0</Cy>
        <focalLength>0</focalLength>
        <hackBaseline>0</hackBaseline>
      </plugin>
    </sensor>
  </gazebo>
  <!-- Foot contacts. -->
  <gazebo reference="front_right_calf">
    <sensor name="front_right_foot_contact" type="contact">
      <update_rate>100</update_rate>
      <plugin filename="libunitreeFootContactPlugin.so" name="contactPlugin"/>
      <contact>
        <collision>FR_calf_fixed_joint_lump__FR_foot_collision_1</collision>
      </contact>
    </sensor>
  </gazebo>
  <gazebo reference="front_left_calf">
    <sensor name="front_left_foot_contact" type="contact">
      <update_rate>100</update_rate>
      <plugin filename="libunitreeFootContactPlugin.so" name="contactPlugin"/>
      <contact>
        <collision>FL_calf_fixed_joint_lump__FL_foot_collision_1</collision>
      </contact>
    </sensor>
  </gazebo>
  <gazebo reference="back_right_calf">
    <sensor name="back_right_foot_contact" type="contact">
      <update_rate>100</update_rate>
      <plugin filename="libunitreeFootContactPlugin.so" name="contactPlugin"/>
      <contact>
        <collision>RR_calf_fixed_joint_lump__RR_foot_collision_1</collision>
      </contact>
    </sensor>
  </gazebo>
  <gazebo reference="back_left_calf">
    <sensor name="back_left_foot_contact" type="contact">
      <update_rate>100</update_rate>
      <plugin filename="libunitreeFootContactPlugin.so" name="contactPlugin"/>
      <contact>
        <collision>RL_calf_fixed_joint_lump__RL_foot_collision_1</collision>
      </contact>
    </sensor>
  </gazebo>
  <!-- Visualization of Foot contacts. -->
  <gazebo reference="front_right_foot">
    <visual>
      <plugin filename="libunitreeDrawForcePlugin.so" name="drawForcePlugin">
        <topicName>FR_foot_contact</topicName>
      </plugin>
    </visual>
  </gazebo>
  <gazebo reference="front_left_foot">
    <visual>
      <plugin filename="libunitreeDrawForcePlugin.so" name="drawForcePlugin">
        <topicName>FL_foot_contact</topicName>
      </plugin>
    </visual>
  </gazebo>
  <gazebo reference="back_right_foot">
    <visual>
      <plugin filename="libunitreeDrawForcePlugin.so" name="drawForcePlugin">
        <topicName>RR_foot_contact</topicName>
      </plugin>
    </visual>
  </gazebo>
  <gazebo reference="back_left_foot">
    <visual>
      <plugin filename="libunitreeDrawForcePlugin.so" name="drawForcePlugin">
        <topicName>RL_foot_contact</topicName>
      </plugin>
    </visual>
  </gazebo>
  <gazebo reference="base_link">
    <material>Gazebo/Green</material>
    <turnGravityOff>false</turnGravityOff>
  </gazebo>
  <gazebo reference="trunk">
    <mu1>0.2</mu1>
    <mu2>0.2</mu2>
    <kp value="1000000.0"/>
    <kd value="1.0"/>
  </gazebo>
  <gazebo reference="stick_link">
    <mu1>0.2</mu1>
    <mu2>0.2</mu2>
    <material>Gazebo/White</material>
  </gazebo>
  <gazebo reference="imu_link">
    <mu1>0.2</mu1>
    <mu2>0.2</mu2>
    <material>Gazebo/Red</material>
  </gazebo>
  <!-- FL leg -->
  <gazebo reference="front_left_hip">
    <mu1>0.2</mu1>
    <mu2>0.2</mu2>
    <material>Gazebo/DarkGrey</material>
  </gazebo>
  <gazebo reference="front_left_thigh">
    <mu1>0.2</mu1>
    <mu2>0.2</mu2>
    <self_collide>1</self_collide>
    <material>Gazebo/DarkGrey</material>
    <kp value="1000000.0"/>
    <kd value="1.0"/>
  </gazebo>
  <gazebo reference="front_left_calf">
    <mu1>0.2</mu1>
    <mu2>0.2</mu2>
    <self_collide>1</self_collide>
  </gazebo>
  <gazebo reference="front_left_foot">
    <mu1>0.6</mu1> <!-- 0.6 -->
    <mu2>0.6</mu2> <!-- 0.6 -->
    <self_collide>1</self_collide>
    <material>Gazebo/DarkGrey</material>
    <kp value="1000000.0"/>
    <kd value="1.0"/>
  </gazebo>
  <!-- FR leg -->
  <gazebo reference="front_right_hip">
    <mu1>0.2</mu1>
    <mu2>0.2</mu2>
    <material>Gazebo/DarkGrey</material>
  </gazebo>
  <gazebo reference="front_right_thigh">
    <mu1>0.2</mu1>
    <mu2>0.2</mu2>
    <self_collide>1</self_collide>
    <material>Gazebo/DarkGrey</material>
    <kp value="1000000.0"/>
    <kd value="1.0"/>
  </gazebo>
  <gazebo reference="front_right_calf">
    <mu1>0.2</mu1>
    <mu2>0.2</mu2>
    <self_collide>1</self_collide>
  </gazebo>
  <gazebo reference="front_right_foot">
    <mu1>0.6</mu1>
    <mu2>0.6</mu2>
    <self_collide>1</self_collide>
    <material>Gazebo/DarkGrey</material>
    <kp value="1000000.0"/>
    <kd value="1.0"/>
  </gazebo>
  <!-- RL leg -->
  <gazebo reference="back_left_hip">
    <mu1>0.2</mu1>
    <mu2>0.2</mu2>
    <material>Gazebo/DarkGrey</material>
  </gazebo>
  <gazebo reference="back_left_thigh">
    <mu1>0.2</mu1>
    <mu2>0.2</mu2>
    <self_collide>1</self_collide>
    <material>Gazebo/DarkGrey</material>
    <kp value="1000000.0"/>
    <kd value="1.0"/>
  </gazebo>
  <gazebo reference="back_left_calf">
    <mu1>0.2</mu1>
    <mu2>0.2</mu2>
    <self_collide>1</self_collide>
  </gazebo>
  <gazebo reference="back_left_foot">
    <mu1>0.6</mu1>
    <mu2>0.6</mu2>
    <self_collide>1</self_collide>
    <material>Gazebo/DarkGrey</material>
    <kp value="1000000.0"/>
    <kd value="1.0"/>
  </gazebo>
  <!-- RR leg -->
  <gazebo reference="back_right_hip">
    <mu1>0.2</mu1>
    <mu2>0.2</mu2>
    <material>Gazebo/DarkGrey</material>
  </gazebo>
  <gazebo reference="back_right_thigh">
    <mu1>0.2</mu1>
    <mu2>0.2</mu2>
    <self_collide>1</self_collide>
    <material>Gazebo/DarkGrey</material>
    <kp value="1000000.0"/>
    <kd value="1.0"/>
  </gazebo>
  <gazebo reference="back_right_calf">
    <mu1>0.2</mu1>
    <mu2>0.2</mu2>
    <self_collide>1</self_collide>
  </gazebo>
  <gazebo reference="back_right_foot">
    <mu1>0.6</mu1>
    <mu2>0.6</mu2>
    <self_collide>1</self_collide>
    <material>Gazebo/DarkGrey</material>
    <kp value="1000000.0"/>
    <kd value="1.0"/>
  </gazebo>
  <!-- <xacro:stairs stairs="15" xpos="0" ypos="0" zpos="0" /> -->
  <!-- Rotor related joint and link is only for demonstrate location. -->
  <!-- Actually, the rotor will rotate and the joint is not fixed. Reduction ratio should be considered. -->
  <link name="base_link">
    <visual>
      <origin rpy="0 0 0" xyz="0 0 0"/>
      <geometry>
        <box size="0.001 0.001 0.001"/>
      </geometry>
    </visual>
  </link>
  <joint name="floating_base" type="fixed">
    <origin rpy="0 0 1.57" xyz="0 0 0"/>
    <parent link="base_link"/>
    <child link="trunk"/>
  </joint>
  <link name="trunk">
    <visual>
      <origin rpy="0 0 0" xyz="0 0 0"/>
      <geometry>
        <mesh filename="package://go1_description/meshes/trunk.dae" scale="1 1 1"/>
      </geometry>
      <material name="orange"/>
    </visual>
    <collision>
      <origin rpy="0 0 0" xyz="0 0 0"/>
      <geometry>
        <box size="0.3762 0.0935 0.114"/>
      </geometry>
    </collision>
    <inertial>
      <origin rpy="0 0 0" xyz="0.0223 0.002 -0.0005"/>
      <mass value="5.204"/>
      <inertia ixx="0.0168128557" ixy="-0.0002296769" ixz="-0.0002945293" iyy="0.063009565" iyz="-4.18731e-05" izz="0.0716547275"/>
    </inertial>
  </link>
  <joint name="imu_joint" type="fixed">
    <parent link="trunk"/>
    <child link="imu_link"/>
    <origin rpy="0 0 0" xyz="-0.01592 -0.06659 -0.00617"/>
  </joint>
  <link name="imu_link">
    <inertial>
      <mass value="0.001"/>
      <origin rpy="0 0 0" xyz="0 0 0"/>
      <inertia ixx="0.0001" ixy="0" ixz="0" iyy="0.0001" iyz="0" izz="0.0001"/>
    </inertial>
    <visual>
      <origin rpy="0 0 0" xyz="0 0 0"/>
      <geometry>
        <box size="0.001 0.001 0.001"/>
      </geometry>
      <!-- <material name="red"/> -->
    </visual>
    <collision>
      <origin rpy="0 0 0" xyz="0 0 0"/>
      <geometry>
        <box size=".001 .001 .001"/>
      </geometry>
    </collision>
  </link>
  <joint name="front_right_hip_joint" type="revolute">
    <origin rpy="0 0 0" xyz="0.1881 -0.04675 0"/>
    <parent link="trunk"/>
    <child link="front_right_hip"/>
    <axis xyz="1 0 0"/>
    <dynamics damping="0.01" friction="0.2"/>
    <limit effort="23.7" lower="-0.863" upper="0.863" velocity="30.1"/>
  </joint>
  <joint name="front_right_hip_rotor_joint" type="fixed">
    <origin rpy="0 0 0" xyz="0.11215 -0.04675 0"/>
    <parent link="trunk"/>
    <child link="front_right_hip_rotor"/>
  </joint>
  <link name="front_right_hip">
    <visual>
      <origin rpy="3.141592653589793 0 0" xyz="0 0 0"/>
      <geometry>
        <mesh filename="package://go1_description/meshes/hip.dae" scale="1 1 1"/>
      </geometry>
      <!-- <material name="orange"/> -->
    </visual>
    <collision>
      <origin rpy="1.5707963267948966 0 0" xyz="0 -0.08 0"/>
      <geometry>
        <cylinder length="0.04" radius="0.046"/>
      </geometry>
    </collision>
    <inertial>
      <origin rpy="0 0 0" xyz="-0.005657 0.008752 -0.000102"/>
      <mass value="0.591"/>
      <inertia ixx="0.000334008405" ixy="1.0826066e-05" ixz="1.290732e-06" iyy="0.000619101213" iyz="-1.643194e-06" izz="0.00040057614"/>
    </inertial>
  </link>
  <link name="front_right_hip_rotor">
    <visual>
      <origin rpy="0 1.5707963267948966 0" xyz="0 0 0"/>
      <geometry>
        <cylinder length="0.02" radius="0.035"/>
      </geometry>
      <material name="green"/>
    </visual>
    <!-- <collision>
                <origin rpy="0 ${PI/2.0} 0" xyz="0 0 0"/>
                <geometry>
                    <cylinder length="0.02" radius="0.035"/>
                </geometry>
            </collision> -->
    <inertial>
      <origin rpy="0 0 0" xyz="0.0 0.0 0.0"/>
      <mass value="0.089"/>
      <inertia ixx="0.000111842" ixy="0.0" ixz="0.0" iyy="5.9647e-05" iyz="0.0" izz="5.9647e-05"/>
    </inertial>
  </link>
  <joint name="front_right_thigh_joint" type="revolute">
    <origin rpy="0 0 0" xyz="0 -0.08 0"/>
    <parent link="front_right_hip"/>
    <child link="front_right_thigh"/>
    <axis xyz="0 1 0"/>
    <dynamics damping="0.01" friction="0.2"/>
    <limit effort="23.7" lower="-0.686" upper="4.501" velocity="30.1"/>
  </joint>
  <joint name="front_right_thigh_rotor_joint" type="fixed">
    <origin rpy="0 0 0" xyz="0.0 0.00015 0"/>
    <parent link="front_right_hip"/>
    <child link="front_right_thigh_rotor"/>
  </joint>
  <link name="front_right_thigh">
    <visual>
      <origin rpy="0 0 0" xyz="0 0 0"/>
      <geometry>
        <mesh filename="package://go1_description/meshes/thigh_mirror.dae" scale="1 1 1"/>
      </geometry>
      <!-- <material name="orange"/> -->
    </visual>
    <collision>
      <origin rpy="0 1.5707963267948966 0" xyz="0 0 -0.1065"/>
      <geometry>
        <box size="0.213 0.0245 0.034"/>
      </geometry>
    </collision>
    <inertial>
      <origin rpy="0 0 0" xyz="-0.003342 0.018054 -0.033451"/>
      <mass value="0.92"/>
      <inertia ixx="0.004431760472" ixy="-5.7496807e-05" ixz="-0.000218457134" iyy="0.004485671726" iyz="-0.000572001265" izz="0.000740309489"/>
    </inertial>
  </link>
  <link name="front_right_thigh_rotor">
    <visual>
      <origin rpy="1.5707963267948966 0 0" xyz="0 0 0"/>
      <geometry>
        <cylinder length="0.02" radius="0.035"/>
      </geometry>
      <material name="green"/>
    </visual>
    <!-- <collision>
                <origin rpy="${PI/2.0} 0 0" xyz="0 0 0"/>
                <geometry>
                    <cylinder length="0.02" radius="0.035"/>
                </geometry>
            </collision> -->
    <inertial>
      <origin rpy="0 0 0" xyz="0.0 0.0 0.0"/>
      <mass value="0.089"/>
      <inertia ixx="5.9647e-05" ixy="0.0" ixz="0.0" iyy="0.000111842" iyz="0.0" izz="5.9647e-05"/>
    </inertial>
  </link>
  <joint name="front_right_calf_joint" type="revolute">
    <origin rpy="0 0 0" xyz="0 0 -0.213"/>
    <parent link="front_right_thigh"/>
    <child link="front_right_calf"/>
    <axis xyz="0 1 0"/>
    <dynamics damping="0.01" friction="0.2"/>
    <limit effort="35.55" lower="-2.818" upper="-0.888" velocity="20.06"/>
  </joint>
  <joint name="front_right_calf_rotor_joint" type="fixed">
    <origin rpy="0 0 0" xyz="0.0 0.03235 0"/>
    <parent link="front_right_thigh"/>
    <child link="front_right_calf_rotor"/>
  </joint>
  <link name="front_right_calf">
    <visual>
      <origin rpy="0 0 0" xyz="0 0 0"/>
      <geometry>
        <mesh filename="package://go1_description/meshes/calf.dae" scale="1 1 1"/>
      </geometry>
      <!-- <material name="orange"/> -->
    </visual>
    <collision>
      <origin rpy="0 1.5707963267948966 0" xyz="0 0 -0.1065"/>
      <geometry>
        <box size="0.213 0.016 0.016"/>
      </geometry>
    </collision>
    <inertial>
      <origin rpy="0 0 0" xyz="0.006197 0.001408 -0.116695"/>
      <mass value="0.135862"/>
      <inertia ixx="0.001088793059" ixy="-2.55679e-07" ixz="7.117814e-06" iyy="0.001100428748" iyz="2.077264e-06" izz="2.4787446e-05"/>
    </inertial>
  </link>
  <link name="front_right_calf_rotor">
    <visual>
      <origin rpy="1.5707963267948966 0 0" xyz="0 0 0"/>
      <geometry>
        <cylinder length="0.02" radius="0.035"/>
      </geometry>
      <material name="green"/>
    </visual>
    <!-- <collision>
                <origin rpy="${PI/2.0} 0 0" xyz="0 0 0"/>
                <geometry>
                    <cylinder length="0.02" radius="0.035"/>
                </geometry>
            </collision> -->
    <inertial>
      <origin rpy="0 0 0" xyz="0.0 0.0 0.0"/>
      <mass value="0.089"/>
      <inertia ixx="5.9647e-05" ixy="0.0" ixz="0.0" iyy="0.000111842" iyz="0.0" izz="5.9647e-05"/>
    </inertial>
  </link>
  <joint name="front_right_foot_fixed" type="fixed">
    <origin rpy="0 0 0" xyz="0 0 -0.213"/>
    <parent link="front_right_calf"/>
    <child link="front_right_foot"/>
  </joint>
  <link name="front_right_foot">
    <visual>
      <origin rpy="0 0 0" xyz="0 0 0"/>
      <geometry>
        <sphere radius="0.01"/>
      </geometry>
      <!-- <material name="orange"/> -->
    </visual>
    <collision>
      <origin rpy="0 0 0" xyz="0 0 0"/>
      <geometry>
        <sphere radius="0.02"/>
      </geometry>
    </collision>
    <inertial>
      <mass value="0.06"/>
      <inertia ixx="9.600000000000001e-06" ixy="0.0" ixz="0.0" iyy="9.600000000000001e-06" iyz="0.0" izz="9.600000000000001e-06"/>
    </inertial>
  </link>
  <transmission name="front_right_hip_tran">
    <type>transmission_interface/SimpleTransmission</type>
    <joint name="front_right_hip_joint">
      <hardwareInterface>hardware_interface/EffortJointInterface</hardwareInterface>
    </joint>
    <actuator name="front_right_hip_motor">
      <hardwareInterface>hardware_interface/EffortJointInterface</hardwareInterface>
      <mechanicalReduction>1</mechanicalReduction>
    </actuator>
  </transmission>
  <transmission name="front_right_thigh_tran">
    <type>transmission_interface/SimpleTransmission</type>
    <joint name="front_right_thigh_joint">
      <hardwareInterface>hardware_interface/EffortJointInterface</hardwareInterface>
    </joint>
    <actuator name="front_right_thigh_motor">
      <hardwareInterface>hardware_interface/EffortJointInterface</hardwareInterface>
      <mechanicalReduction>1</mechanicalReduction>
    </actuator>
  </transmission>
  <transmission name="front_right_calf_tran">
    <type>transmission_interface/SimpleTransmission</type>
    <joint name="front_right_calf_joint">
      <hardwareInterface>hardware_interface/EffortJointInterface</hardwareInterface>
    </joint>
    <actuator name="front_right_calf_motor">
      <hardwareInterface>hardware_interface/EffortJointInterface</hardwareInterface>
      <mechanicalReduction>1</mechanicalReduction>
    </actuator>
  </transmission>
  <joint name="front_left_hip_joint" type="revolute">
    <origin rpy="0 0 0" xyz="0.1881 0.04675 0"/>
    <parent link="trunk"/>
    <child link="front_left_hip"/>
    <axis xyz="1 0 0"/>
    <dynamics damping="0.01" friction="0.2"/>
    <limit effort="23.7" lower="-0.863" upper="0.863" velocity="30.1"/>
  </joint>
  <joint name="front_left_hip_rotor_joint" type="fixed">
    <origin rpy="0 0 0" xyz="0.11215 0.04675 0"/>
    <parent link="trunk"/>
    <child link="front_left_hip_rotor"/>
  </joint>
  <link name="front_left_hip">
    <visual>
      <origin rpy="0 0 0" xyz="0 0 0"/>
      <geometry>
        <mesh filename="package://go1_description/meshes/hip.dae" scale="1 1 1"/>
      </geometry>
      <!-- <material name="orange"/> -->
    </visual>
    <collision>
      <origin rpy="1.5707963267948966 0 0" xyz="0 0.08 0"/>
      <geometry>
        <cylinder length="0.04" radius="0.046"/>
      </geometry>
    </collision>
    <inertial>
      <origin rpy="0 0 0" xyz="-0.005657 -0.008752 -0.000102"/>
      <mass value="0.591"/>
      <inertia ixx="0.000334008405" ixy="-1.0826066e-05" ixz="1.290732e-06" iyy="0.000619101213" iyz="1.643194e-06" izz="0.00040057614"/>
    </inertial>
  </link>
  <link name="front_left_hip_rotor">
    <visual>
      <origin rpy="0 1.5707963267948966 0" xyz="0 0 0"/>
      <geometry>
        <cylinder length="0.02" radius="0.035"/>
      </geometry>
      <material name="green"/>
    </visual>
    <!-- <collision>
                <origin rpy="0 ${PI/2.0} 0" xyz="0 0 0"/>
                <geometry>
                    <cylinder length="0.02" radius="0.035"/>
                </geometry>
            </collision> -->
    <inertial>
      <origin rpy="0 0 0" xyz="0.0 0.0 0.0"/>
      <mass value="0.089"/>
      <inertia ixx="0.000111842" ixy="0.0" ixz="0.0" iyy="5.9647e-05" iyz="0.0" izz="5.9647e-05"/>
    </inertial>
  </link>
  <joint name="front_left_thigh_joint" type="revolute">
    <origin rpy="0 0 0" xyz="0 0.08 0"/>
    <parent link="front_left_hip"/>
    <child link="front_left_thigh"/>
    <axis xyz="0 1 0"/>
    <dynamics damping="0.01" friction="0.2"/>
    <limit effort="23.7" lower="-0.686" upper="4.501" velocity="30.1"/>
  </joint>
  <joint name="front_left_thigh_rotor_joint" type="fixed">
    <origin rpy="0 0 0" xyz="0.0 -0.00015 0"/>
    <parent link="front_left_hip"/>
    <child link="front_left_thigh_rotor"/>
  </joint>
  <link name="front_left_thigh">
    <visual>
      <origin rpy="0 0 0" xyz="0 0 0"/>
      <geometry>
        <mesh filename="package://go1_description/meshes/thigh.dae" scale="1 1 1"/>
      </geometry>
      <!-- <material name="orange"/> -->
    </visual>
    <collision>
      <origin rpy="0 1.5707963267948966 0" xyz="0 0 -0.1065"/>
      <geometry>
        <box size="0.213 0.0245 0.034"/>
      </geometry>
    </collision>
    <inertial>
      <origin rpy="0 0 0" xyz="-0.003342 -0.018054 -0.033451"/>
      <mass value="0.92"/>
      <inertia ixx="0.004431760472" ixy="5.7496807e-05" ixz="-0.000218457134" iyy="0.004485671726" iyz="0.000572001265" izz="0.000740309489"/>
    </inertial>
  </link>
  <link name="front_left_thigh_rotor">
    <visual>
      <origin rpy="1.5707963267948966 0 0" xyz="0 0 0"/>
      <geometry>
        <cylinder length="0.02" radius="0.035"/>
      </geometry>
      <material name="green"/>
    </visual>
    <!-- <collision>
                <origin rpy="${PI/2.0} 0 0" xyz="0 0 0"/>
                <geometry>
                    <cylinder length="0.02" radius="0.035"/>
                </geometry>
            </collision> -->
    <inertial>
      <origin rpy="0 0 0" xyz="0.0 0.0 0.0"/>
      <mass value="0.089"/>
      <inertia ixx="5.9647e-05" ixy="0.0" ixz="0.0" iyy="0.000111842" iyz="0.0" izz="5.9647e-05"/>
    </inertial>
  </link>
  <joint name="front_left_calf_joint" type="revolute">
    <origin rpy="0 0 0" xyz="0 0 -0.213"/>
    <parent link="front_left_thigh"/>
    <child link="front_left_calf"/>
    <axis xyz="0 1 0"/>
    <dynamics damping="0.01" friction="0.2"/>
    <limit effort="35.55" lower="-2.818" upper="-0.888" velocity="20.06"/>
  </joint>
  <joint name="front_left_calf_rotor_joint" type="fixed">
    <origin rpy="0 0 0" xyz="0.0 -0.03235 0"/>
    <parent link="front_left_thigh"/>
    <child link="front_left_calf_rotor"/>
  </joint>
  <link name="front_left_calf">
    <visual>
      <origin rpy="0 0 0" xyz="0 0 0"/>
      <geometry>
        <mesh filename="package://go1_description/meshes/calf.dae" scale="1 1 1"/>
      </geometry>
      <!-- <material name="orange"/> -->
    </visual>
    <collision>
      <origin rpy="0 1.5707963267948966 0" xyz="0 0 -0.1065"/>
      <geometry>
        <box size="0.213 0.016 0.016"/>
      </geometry>
    </collision>
    <inertial>
      <origin rpy="0 0 0" xyz="0.006197 0.001408 -0.116695"/>
      <mass value="0.135862"/>
      <inertia ixx="0.001088793059" ixy="-2.55679e-07" ixz="7.117814e-06" iyy="0.001100428748" iyz="2.077264e-06" izz="2.4787446e-05"/>
    </inertial>
  </link>
  <link name="front_left_calf_rotor">
    <visual>
      <origin rpy="1.5707963267948966 0 0" xyz="0 0 0"/>
      <geometry>
        <cylinder length="0.02" radius="0.035"/>
      </geometry>
      <material name="green"/>
    </visual>
    <!-- <collision>
                <origin rpy="${PI/2.0} 0 0" xyz="0 0 0"/>
                <geometry>
                    <cylinder length="0.02" radius="0.035"/>
                </geometry>
            </collision> -->
    <inertial>
      <origin rpy="0 0 0" xyz="0.0 0.0 0.0"/>
      <mass value="0.089"/>
      <inertia ixx="5.9647e-05" ixy="0.0" ixz="0.0" iyy="0.000111842" iyz="0.0" izz="5.9647e-05"/>
    </inertial>
  </link>
  <joint name="front_left_foot_fixed" type="fixed">
    <origin rpy="0 0 0" xyz="0 0 -0.213"/>
    <parent link="front_left_calf"/>
    <child link="front_left_foot"/>
  </joint>
  <link name="front_left_foot">
    <visual>
      <origin rpy="0 0 0" xyz="0 0 0"/>
      <geometry>
        <sphere radius="0.01"/>
      </geometry>
      <!-- <material name="orange"/> -->
    </visual>
    <collision>
      <origin rpy="0 0 0" xyz="0 0 0"/>
      <geometry>
        <sphere radius="0.02"/>
      </geometry>
    </collision>
    <inertial>
      <mass value="0.06"/>
      <inertia ixx="9.600000000000001e-06" ixy="0.0" ixz="0.0" iyy="9.600000000000001e-06" iyz="0.0" izz="9.600000000000001e-06"/>
    </inertial>
  </link>
  <transmission name="front_left_hip_tran">
    <type>transmission_interface/SimpleTransmission</type>
    <joint name="front_left_hip_joint">
      <hardwareInterface>hardware_interface/EffortJointInterface</hardwareInterface>
    </joint>
    <actuator name="front_left_hip_motor">
      <hardwareInterface>hardware_interface/EffortJointInterface</hardwareInterface>
      <mechanicalReduction>1</mechanicalReduction>
    </actuator>
  </transmission>
  <transmission name="front_left_thigh_tran">
    <type>transmission_interface/SimpleTransmission</type>
    <joint name="front_left_thigh_joint">
      <hardwareInterface>hardware_interface/EffortJointInterface</hardwareInterface>
    </joint>
    <actuator name="front_left_thigh_motor">
      <hardwareInterface>hardware_interface/EffortJointInterface</hardwareInterface>
      <mechanicalReduction>1</mechanicalReduction>
    </actuator>
  </transmission>
  <transmission name="front_left_calf_tran">
    <type>transmission_interface/SimpleTransmission</type>
    <joint name="front_left_calf_joint">
      <hardwareInterface>hardware_interface/EffortJointInterface</hardwareInterface>
    </joint>
    <actuator name="front_left_calf_motor">
      <hardwareInterface>hardware_interface/EffortJointInterface</hardwareInterface>
      <mechanicalReduction>1</mechanicalReduction>
    </actuator>
  </transmission>
  <joint name="back_right_hip_joint" type="revolute">
    <origin rpy="0 0 0" xyz="-0.1881 -0.04675 0"/>
    <parent link="trunk"/>
    <child link="back_right_hip"/>
    <axis xyz="1 0 0"/>
    <dynamics damping="0.01" friction="0.2"/>
    <limit effort="23.7" lower="-0.863" upper="0.863" velocity="30.1"/>
  </joint>
  <joint name="back_right_hip_rotor_joint" type="fixed">
    <origin rpy="0 0 0" xyz="-0.11215 -0.04675 0"/>
    <parent link="trunk"/>
    <child link="back_right_hip_rotor"/>
  </joint>
  <link name="back_right_hip">
    <visual>
      <origin rpy="3.141592653589793 3.141592653589793 0" xyz="0 0 0"/>
      <geometry>
        <mesh filename="package://go1_description/meshes/hip.dae" scale="1 1 1"/>
      </geometry>
      <!-- <material name="orange"/> -->
    </visual>
    <collision>
      <origin rpy="1.5707963267948966 0 0" xyz="0 -0.08 0"/>
      <geometry>
        <cylinder length="0.04" radius="0.046"/>
      </geometry>
    </collision>
    <inertial>
      <origin rpy="0 0 0" xyz="0.005657 0.008752 -0.000102"/>
      <mass value="0.591"/>
      <inertia ixx="0.000334008405" ixy="-1.0826066e-05" ixz="-1.290732e-06" iyy="0.000619101213" iyz="-1.643194e-06" izz="0.00040057614"/>
    </inertial>
  </link>
  <link name="back_right_hip_rotor">
    <visual>
      <origin rpy="0 1.5707963267948966 0" xyz="0 0 0"/>
      <geometry>
        <cylinder length="0.02" radius="0.035"/>
      </geometry>
      <material name="green"/>
    </visual>
    <!-- <collision>
                <origin rpy="0 ${PI/2.0} 0" xyz="0 0 0"/>
                <geometry>
                    <cylinder length="0.02" radius="0.035"/>
                </geometry>
            </collision> -->
    <inertial>
      <origin rpy="0 0 0" xyz="0.0 0.0 0.0"/>
      <mass value="0.089"/>
      <inertia ixx="0.000111842" ixy="0.0" ixz="0.0" iyy="5.9647e-05" iyz="0.0" izz="5.9647e-05"/>
    </inertial>
  </link>
  <joint name="back_right_thigh_joint" type="revolute">
    <origin rpy="0 0 0" xyz="0 -0.08 0"/>
    <parent link="back_right_hip"/>
    <child link="back_right_thigh"/>
    <axis xyz="0 1 0"/>
    <dynamics damping="0.01" friction="0.2"/>
    <limit effort="23.7" lower="-0.686" upper="4.501" velocity="30.1"/>
  </joint>
  <joint name="back_right_thigh_rotor_joint" type="fixed">
    <origin rpy="0 0 0" xyz="0.0 0.00015 0"/>
    <parent link="back_right_hip"/>
    <child link="back_right_thigh_rotor"/>
  </joint>
  <link name="back_right_thigh">
    <visual>
      <origin rpy="0 0 0" xyz="0 0 0"/>
      <geometry>
        <mesh filename="package://go1_description/meshes/thigh_mirror.dae" scale="1 1 1"/>
      </geometry>
      <!-- <material name="orange"/> -->
    </visual>
    <collision>
      <origin rpy="0 1.5707963267948966 0" xyz="0 0 -0.1065"/>
      <geometry>
        <box size="0.213 0.0245 0.034"/>
      </geometry>
    </collision>
    <inertial>
      <origin rpy="0 0 0" xyz="-0.003342 0.018054 -0.033451"/>
      <mass value="0.92"/>
      <inertia ixx="0.004431760472" ixy="-5.7496807e-05" ixz="-0.000218457134" iyy="0.004485671726" iyz="-0.000572001265" izz="0.000740309489"/>
    </inertial>
  </link>
  <link name="back_right_thigh_rotor">
    <visual>
      <origin rpy="1.5707963267948966 0 0" xyz="0 0 0"/>
      <geometry>
        <cylinder length="0.02" radius="0.035"/>
      </geometry>
      <material name="green"/>
    </visual>
    <!-- <collision>
                <origin rpy="${PI/2.0} 0 0" xyz="0 0 0"/>
                <geometry>
                    <cylinder length="0.02" radius="0.035"/>
                </geometry>
            </collision> -->
    <inertial>
      <origin rpy="0 0 0" xyz="0.0 0.0 0.0"/>
      <mass value="0.089"/>
      <inertia ixx="5.9647e-05" ixy="0.0" ixz="0.0" iyy="0.000111842" iyz="0.0" izz="5.9647e-05"/>
    </inertial>
  </link>
  <joint name="back_right_calf_joint" type="revolute">
    <origin rpy="0 0 0" xyz="0 0 -0.213"/>
    <parent link="back_right_thigh"/>
    <child link="back_right_calf"/>
    <axis xyz="0 1 0"/>
    <dynamics damping="0.01" friction="0.2"/>
    <limit effort="35.55" lower="-2.818" upper="-0.888" velocity="20.06"/>
  </joint>
  <joint name="back_right_calf_rotor_joint" type="fixed">
    <origin rpy="0 0 0" xyz="0.0 0.03235 0"/>
    <parent link="back_right_thigh"/>
    <child link="back_right_calf_rotor"/>
  </joint>
  <link name="back_right_calf">
    <visual>
      <origin rpy="0 0 0" xyz="0 0 0"/>
      <geometry>
        <mesh filename="package://go1_description/meshes/calf.dae" scale="1 1 1"/>
      </geometry>
      <!-- <material name="orange"/> -->
    </visual>
    <collision>
      <origin rpy="0 1.5707963267948966 0" xyz="0 0 -0.1065"/>
      <geometry>
        <box size="0.213 0.016 0.016"/>
      </geometry>
    </collision>
    <inertial>
      <origin rpy="0 0 0" xyz="0.006197 0.001408 -0.116695"/>
      <mass value="0.135862"/>
      <inertia ixx="0.001088793059" ixy="-2.55679e-07" ixz="7.117814e-06" iyy="0.001100428748" iyz="2.077264e-06" izz="2.4787446e-05"/>
    </inertial>
  </link>
  <link name="back_right_calf_rotor">
    <visual>
      <origin rpy="1.5707963267948966 0 0" xyz="0 0 0"/>
      <geometry>
        <cylinder length="0.02" radius="0.035"/>
      </geometry>
      <material name="green"/>
    </visual>
    <!-- <collision>
                <origin rpy="${PI/2.0} 0 0" xyz="0 0 0"/>
                <geometry>
                    <cylinder length="0.02" radius="0.035"/>
                </geometry>
            </collision> -->
    <inertial>
      <origin rpy="0 0 0" xyz="0.0 0.0 0.0"/>
      <mass value="0.089"/>
      <inertia ixx="5.9647e-05" ixy="0.0" ixz="0.0" iyy="0.000111842" iyz="0.0" izz="5.9647e-05"/>
    </inertial>
  </link>
  <joint name="back_right_foot_fixed" type="fixed">
    <origin rpy="0 0 0" xyz="0 0 -0.213"/>
    <parent link="back_right_calf"/>
    <child link="back_right_foot"/>
  </joint>
  <link name="back_right_foot">
    <visual>
      <origin rpy="0 0 0" xyz="0 0 0"/>
      <geometry>
        <sphere radius="0.01"/>
      </geometry>
      <!-- <material name="orange"/> -->
    </visual>
    <collision>
      <origin rpy="0 0 0" xyz="0 0 0"/>
      <geometry>
        <sphere radius="0.02"/>
      </geometry>
    </collision>
    <inertial>
      <mass value="0.06"/>
      <inertia ixx="9.600000000000001e-06" ixy="0.0" ixz="0.0" iyy="9.600000000000001e-06" iyz="0.0" izz="9.600000000000001e-06"/>
    </inertial>
  </link>
  <transmission name="back_right_hip_tran">
    <type>transmission_interface/SimpleTransmission</type>
    <joint name="back_right_hip_joint">
      <hardwareInterface>hardware_interface/EffortJointInterface</hardwareInterface>
    </joint>
    <actuator name="back_right_hip_motor">
      <hardwareInterface>hardware_interface/EffortJointInterface</hardwareInterface>
      <mechanicalReduction>1</mechanicalReduction>
    </actuator>
  </transmission>
  <transmission name="back_right_thigh_tran">
    <type>transmission_interface/SimpleTransmission</type>
    <joint name="back_right_thigh_joint">
      <hardwareInterface>hardware_interface/EffortJointInterface</hardwareInterface>
    </joint>
    <actuator name="back_right_thigh_motor">
      <hardwareInterface>hardware_interface/EffortJointInterface</hardwareInterface>
      <mechanicalReduction>1</mechanicalReduction>
    </actuator>
  </transmission>
  <transmission name="back_right_calf_tran">
    <type>transmission_interface/SimpleTransmission</type>
    <joint name="back_right_calf_joint">
      <hardwareInterface>hardware_interface/EffortJointInterface</hardwareInterface>
    </joint>
    <actuator name="back_right_calf_motor">
      <hardwareInterface>hardware_interface/EffortJointInterface</hardwareInterface>
      <mechanicalReduction>1</mechanicalReduction>
    </actuator>
  </transmission>
  <joint name="back_left_hip_joint" type="revolute">
    <origin rpy="0 0 0" xyz="-0.1881 0.04675 0"/>
    <parent link="trunk"/>
    <child link="back_left_hip"/>
    <axis xyz="1 0 0"/>
    <dynamics damping="0.01" friction="0.2"/>
    <limit effort="23.7" lower="-0.863" upper="0.863" velocity="30.1"/>
  </joint>
  <joint name="back_left_hip_rotor_joint" type="fixed">
    <origin rpy="0 0 0" xyz="-0.11215 0.04675 0"/>
    <parent link="trunk"/>
    <child link="back_left_hip_rotor"/>
  </joint>
  <link name="back_left_hip">
    <visual>
      <origin rpy="0 3.141592653589793 0" xyz="0 0 0"/>
      <geometry>
        <mesh filename="package://go1_description/meshes/hip.dae" scale="1 1 1"/>
      </geometry>
      <!-- <material name="orange"/> -->
    </visual>
    <collision>
      <origin rpy="1.5707963267948966 0 0" xyz="0 0.08 0"/>
      <geometry>
        <cylinder length="0.04" radius="0.046"/>
      </geometry>
    </collision>
    <inertial>
      <origin rpy="0 0 0" xyz="0.005657 -0.008752 -0.000102"/>
      <mass value="0.591"/>
      <inertia ixx="0.000334008405" ixy="1.0826066e-05" ixz="-1.290732e-06" iyy="0.000619101213" iyz="1.643194e-06" izz="0.00040057614"/>
    </inertial>
  </link>
  <link name="back_left_hip_rotor">
    <visual>
      <origin rpy="0 1.5707963267948966 0" xyz="0 0 0"/>
      <geometry>
        <cylinder length="0.02" radius="0.035"/>
      </geometry>
      <material name="green"/>
    </visual>
    <!-- <collision>
                <origin rpy="0 ${PI/2.0} 0" xyz="0 0 0"/>
                <geometry>
                    <cylinder length="0.02" radius="0.035"/>
                </geometry>
            </collision> -->
    <inertial>
      <origin rpy="0 0 0" xyz="0.0 0.0 0.0"/>
      <mass value="0.089"/>
      <inertia ixx="0.000111842" ixy="0.0" ixz="0.0" iyy="5.9647e-05" iyz="0.0" izz="5.9647e-05"/>
    </inertial>
  </link>
  <joint name="back_left_thigh_joint" type="revolute">
    <origin rpy="0 0 0" xyz="0 0.08 0"/>
    <parent link="back_left_hip"/>
    <child link="back_left_thigh"/>
    <axis xyz="0 1 0"/>
    <dynamics damping="0.01" friction="0.2"/>
    <limit effort="23.7" lower="-0.686" upper="4.501" velocity="30.1"/>
  </joint>
  <joint name="back_left_thigh_rotor_joint" type="fixed">
    <origin rpy="0 0 0" xyz="0.0 -0.00015 0"/>
    <parent link="back_left_hip"/>
    <child link="back_left_thigh_rotor"/>
  </joint>
  <link name="back_left_thigh">
    <visual>
      <origin rpy="0 0 0" xyz="0 0 0"/>
      <geometry>
        <mesh filename="package://go1_description/meshes/thigh.dae" scale="1 1 1"/>
      </geometry>
      <!-- <material name="orange"/> -->
    </visual>
    <collision>
      <origin rpy="0 1.5707963267948966 0" xyz="0 0 -0.1065"/>
      <geometry>
        <box size="0.213 0.0245 0.034"/>
      </geometry>
    </collision>
    <inertial>
      <origin rpy="0 0 0" xyz="-0.003342 -0.018054 -0.033451"/>
      <mass value="0.92"/>
      <inertia ixx="0.004431760472" ixy="5.7496807e-05" ixz="-0.000218457134" iyy="0.004485671726" iyz="0.000572001265" izz="0.000740309489"/>
    </inertial>
  </link>
  <link name="back_left_thigh_rotor">
    <visual>
      <origin rpy="1.5707963267948966 0 0" xyz="0 0 0"/>
      <geometry>
        <cylinder length="0.02" radius="0.035"/>
      </geometry>
      <material name="green"/>
    </visual>
    <!-- <collision>
                <origin rpy="${PI/2.0} 0 0" xyz="0 0 0"/>
                <geometry>
                    <cylinder length="0.02" radius="0.035"/>
                </geometry>
            </collision> -->
    <inertial>
      <origin rpy="0 0 0" xyz="0.0 0.0 0.0"/>
      <mass value="0.089"/>
      <inertia ixx="5.9647e-05" ixy="0.0" ixz="0.0" iyy="0.000111842" iyz="0.0" izz="5.9647e-05"/>
    </inertial>
  </link>
  <joint name="back_left_calf_joint" type="revolute">
    <origin rpy="0 0 0" xyz="0 0 -0.213"/>
    <parent link="back_left_thigh"/>
    <child link="back_left_calf"/>
    <axis xyz="0 1 0"/>
    <dynamics damping="0.01" friction="0.2"/>
    <limit effort="35.55" lower="-2.818" upper="-0.888" velocity="20.06"/>
  </joint>
  <joint name="back_left_calf_rotor_joint" type="fixed">
    <origin rpy="0 0 0" xyz="0.0 -0.03235 0"/>
    <parent link="back_left_thigh"/>
    <child link="back_left_calf_rotor"/>
  </joint>
  <link name="back_left_calf">
    <visual>
      <origin rpy="0 0 0" xyz="0 0 0"/>
      <geometry>
        <mesh filename="package://go1_description/meshes/calf.dae" scale="1 1 1"/>
      </geometry>
      <!-- <material name="orange"/> -->
    </visual>
    <collision>
      <origin rpy="0 1.5707963267948966 0" xyz="0 0 -0.1065"/>
      <geometry>
        <box size="0.213 0.016 0.016"/>
      </geometry>
    </collision>
    <inertial>
      <origin rpy="0 0 0" xyz="0.006197 0.001408 -0.116695"/>
      <mass value="0.135862"/>
      <inertia ixx="0.001088793059" ixy="-2.55679e-07" ixz="7.117814e-06" iyy="0.001100428748" iyz="2.077264e-06" izz="2.4787446e-05"/>
    </inertial>
  </link>
  <link name="back_left_calf_rotor">
    <visual>
      <origin rpy="1.5707963267948966 0 0" xyz="0 0 0"/>
      <geometry>
        <cylinder length="0.02" radius="0.035"/>
      </geometry>
      <material name="green"/>
    </visual>
    <!-- <collision>
                <origin rpy="${PI/2.0} 0 0" xyz="0 0 0"/>
                <geometry>
                    <cylinder length="0.02" radius="0.035"/>
                </geometry>
            </collision> -->
    <inertial>
      <origin rpy="0 0 0" xyz="0.0 0.0 0.0"/>
      <mass value="0.089"/>
      <inertia ixx="5.9647e-05" ixy="0.0" ixz="0.0" iyy="0.000111842" iyz="0.0" izz="5.9647e-05"/>
    </inertial>
  </link>
  <joint name="back_left_foot_fixed" type="fixed">
    <origin rpy="0 0 0" xyz="0 0 -0.213"/>
    <parent link="back_left_calf"/>
    <child link="back_left_foot"/>
  </joint>
  <link name="back_left_foot">
    <visual>
      <origin rpy="0 0 0" xyz="0 0 0"/>
      <geometry>
        <sphere radius="0.01"/>
      </geometry>
      <!-- <material name="orange"/> -->
    </visual>
    <collision>
      <origin rpy="0 0 0" xyz="0 0 0"/>
      <geometry>
        <sphere radius="0.02"/>
      </geometry>
    </collision>
    <inertial>
      <mass value="0.06"/>
      <inertia ixx="9.600000000000001e-06" ixy="0.0" ixz="0.0" iyy="9.600000000000001e-06" iyz="0.0" izz="9.600000000000001e-06"/>
    </inertial>
  </link>
  <transmission name="back_left_hip_tran">
    <type>transmission_interface/SimpleTransmission</type>
    <joint name="back_left_hip_joint">
      <hardwareInterface>hardware_interface/EffortJointInterface</hardwareInterface>
    </joint>
    <actuator name="back_left_hip_motor">
      <hardwareInterface>hardware_interface/EffortJointInterface</hardwareInterface>
      <mechanicalReduction>1</mechanicalReduction>
    </actuator>
  </transmission>
  <transmission name="back_left_thigh_tran">
    <type>transmission_interface/SimpleTransmission</type>
    <joint name="back_left_thigh_joint">
      <hardwareInterface>hardware_interface/EffortJointInterface</hardwareInterface>
    </joint>
    <actuator name="back_left_thigh_motor">
      <hardwareInterface>hardware_interface/EffortJointInterface</hardwareInterface>
      <mechanicalReduction>1</mechanicalReduction>
    </actuator>
  </transmission>
  <transmission name="back_left_calf_tran">
    <type>transmission_interface/SimpleTransmission</type>
    <joint name="back_left_calf_joint">
      <hardwareInterface>hardware_interface/EffortJointInterface</hardwareInterface>
    </joint>
    <actuator name="back_left_calf_motor">
      <hardwareInterface>hardware_interface/EffortJointInterface</hardwareInterface>
      <mechanicalReduction>1</mechanicalReduction>
    </actuator>
  </transmission>
  <joint name="camera_joint_face" type="fixed">
    <origin rpy="0 0 0" xyz="0.2785 -0.0125 0.0167"/>
    <parent link="trunk"/>
    <child link="camera_face"/>
  </joint>
  <link name="camera_face">
    <collision>
      <origin rpy="0 0 0" xyz="0 0 0"/>
      <geometry>
        <box size=".001 .001 .001"/>
      </geometry>
    </collision>
    <visual>
      <origin rpy="0 0 0" xyz="0 0 0"/>
      <geometry>
        <mesh filename="package://go1_description/meshes/depthCamera.dae" scale="1 1 1"/>
      </geometry>
    </visual>
    <inertial>
      <mass value="1e-5"/>
      <origin rpy="0 0 0" xyz="0 0 0"/>
      <inertia ixx="1e-6" ixy="0" ixz="0" iyy="1e-6" iyz="0" izz="1e-6"/>
    </inertial>
  </link>
  <joint name="camera_optical_joint_face" type="fixed">
    <origin rpy="-1.5707963267948966 0 -1.5707963267948966" xyz="0 0 0"/>
    <parent link="camera_face"/>
    <child link="camera_optical_face"/>
  </joint>
  <link name="camera_optical_face">
        </link>
  <gazebo reference="camera_face">
    <!-- <material>Gazebo/Black</material> -->
    <sensor name="camera_face_camera" type="depth">
      <update_rate>16</update_rate>
      <camera>
        <horizontal_fov>2.094</horizontal_fov>
        <image>
          <width>928</width>
          <height>800</height>
          <format>B8G8R8</format>
        </image>
        <clip>
          <near>0.1</near>
          <far>5</far>
        </clip>
      </camera>
      <plugin filename="libgazebo_ros_openni_kinect.so" name="camera_face_controller">
        <baseline>0.025</baseline>
        <alwaysOn>true</alwaysOn>
        <updateRate>0.0</updateRate>
        <cameraName>camera_face_ir</cameraName>
        <imageTopicName>/camera_face/color/image_raw</imageTopicName>
        <cameraInfoTopicName>/camera_face/color/camera_info</cameraInfoTopicName>
        <depthImageTopicName>/camera_face/depth/image_raw</depthImageTopicName>
        <depthImageInfoTopicName>/camera_face/depth/camera_info</depthImageInfoTopicName>
        <!-- <pointCloudTopicName>/camera_${name}/depth/points</pointCloudTopicName> -->
        <pointCloudTopicName>/cam1/point_cloud_face</pointCloudTopicName>
        <frameName>camera_optical_face</frameName>
        <pointCloudCutoff>0.1</pointCloudCutoff>
        <pointCloudCutoffMax>1.5</pointCloudCutoffMax>
        <distortionK1>0.0</distortionK1>
        <distortionK2>0.0</distortionK2>
        <distortionK3>0.0</distortionK3>
        <distortionT1>0.0</distortionT1>
        <distortionT2>0.0</distortionT2>
        <CxPrime>0</CxPrime>
        <Cx>0.0045</Cx>
        <Cy>0.0039</Cy>
        <focalLength>0</focalLength>
        <hackBaseline>0</hackBaseline>
      </plugin>
    </sensor>
  </gazebo>
  <joint name="camera_joint_chin" type="fixed">
    <origin rpy="0 1.5707963267948966 0" xyz="0.2522 -0.0125 -0.0436"/>
    <parent link="trunk"/>
    <child link="camera_chin"/>
  </joint>
  <link name="camera_chin">
    <collision>
      <origin rpy="0 0 0" xyz="0 0 0"/>
      <geometry>
        <box size=".001 .001 .001"/>
      </geometry>
    </collision>
    <visual>
      <origin rpy="0 0 0" xyz="0 0 0"/>
      <geometry>
        <mesh filename="package://go1_description/meshes/depthCamera.dae" scale="1 1 1"/>
      </geometry>
    </visual>
    <inertial>
      <mass value="1e-5"/>
      <origin rpy="0 0 0" xyz="0 0 0"/>
      <inertia ixx="1e-6" ixy="0" ixz="0" iyy="1e-6" iyz="0" izz="1e-6"/>
    </inertial>
  </link>
  <joint name="camera_optical_joint_chin" type="fixed">
    <origin rpy="-1.5707963267948966 0 -1.5707963267948966" xyz="0 0 0"/>
    <parent link="camera_chin"/>
    <child link="camera_optical_chin"/>
  </joint>
  <link name="camera_optical_chin">
        </link>
  <gazebo reference="camera_chin">
    <!-- <material>Gazebo/Black</material> -->
    <sensor name="camera_chin_camera" type="depth">
      <update_rate>16</update_rate>
      <camera>
        <horizontal_fov>2.094</horizontal_fov>
        <image>
          <width>928</width>
          <height>800</height>
          <format>B8G8R8</format>
        </image>
        <clip>
          <near>0.1</near>
          <far>5</far>
        </clip>
      </camera>
      <plugin filename="libgazebo_ros_openni_kinect.so" name="camera_chin_controller">
        <baseline>0.025</baseline>
        <alwaysOn>true</alwaysOn>
        <updateRate>0.0</updateRate>
        <cameraName>camera_chin_ir</cameraName>
        <imageTopicName>/camera_chin/color/image_raw</imageTopicName>
        <cameraInfoTopicName>/camera_chin/color/camera_info</cameraInfoTopicName>
        <depthImageTopicName>/camera_chin/depth/image_raw</depthImageTopicName>
        <depthImageInfoTopicName>/camera_chin/depth/camera_info</depthImageInfoTopicName>
        <!-- <pointCloudTopicName>/camera_${name}/depth/points</pointCloudTopicName> -->
        <pointCloudTopicName>/cam2/point_cloud_chin</pointCloudTopicName>
        <frameName>camera_optical_chin</frameName>
        <pointCloudCutoff>0.1</pointCloudCutoff>
        <pointCloudCutoffMax>1.5</pointCloudCutoffMax>
        <distortionK1>0.0</distortionK1>
        <distortionK2>0.0</distortionK2>
        <distortionK3>0.0</distortionK3>
        <distortionT1>0.0</distortionT1>
        <distortionT2>0.0</distortionT2>
        <CxPrime>0</CxPrime>
        <Cx>0.0045</Cx>
        <Cy>0.0039</Cy>
        <focalLength>0</focalLength>
        <hackBaseline>0</hackBaseline>
      </plugin>
    </sensor>
  </gazebo>
  <joint name="camera_joint_left" type="fixed">
    <origin rpy="0 0.2618 1.5707963267948966" xyz="-0.041 0.082 -0.0176"/>
    <parent link="trunk"/>
    <child link="camera_left"/>
  </joint>
  <link name="camera_left">
    <collision>
      <origin rpy="0 0 0" xyz="0 0 0"/>
      <geometry>
        <box size=".001 .001 .001"/>
      </geometry>
    </collision>
    <visual>
      <origin rpy="0 0 0" xyz="0 0 0"/>
      <geometry>
        <mesh filename="package://go1_description/meshes/depthCamera.dae" scale="1 1 1"/>
      </geometry>
    </visual>
    <inertial>
      <mass value="1e-5"/>
      <origin rpy="0 0 0" xyz="0 0 0"/>
      <inertia ixx="1e-6" ixy="0" ixz="0" iyy="1e-6" iyz="0" izz="1e-6"/>
    </inertial>
  </link>
  <joint name="camera_optical_joint_left" type="fixed">
    <origin rpy="-1.5707963267948966 0 -1.5707963267948966" xyz="0 0 0"/>
    <parent link="camera_left"/>
    <child link="camera_optical_left"/>
  </joint>
  <link name="camera_optical_left">
        </link>
  <gazebo reference="camera_left">
    <!-- <material>Gazebo/Black</material> -->
    <sensor name="camera_left_camera" type="depth">
      <update_rate>16</update_rate>
      <camera>
        <horizontal_fov>2.094</horizontal_fov>
        <image>
          <width>928</width>
          <height>800</height>
          <format>B8G8R8</format>
        </image>
        <clip>
          <near>0.1</near>
          <far>5</far>
        </clip>
      </camera>
      <plugin filename="libgazebo_ros_openni_kinect.so" name="camera_left_controller">
        <baseline>0.025</baseline>
        <alwaysOn>true</alwaysOn>
        <updateRate>0.0</updateRate>
        <cameraName>camera_left_ir</cameraName>
        <imageTopicName>/camera_left/color/image_raw</imageTopicName>
        <cameraInfoTopicName>/camera_left/color/camera_info</cameraInfoTopicName>
        <depthImageTopicName>/camera_left/depth/image_raw</depthImageTopicName>
        <depthImageInfoTopicName>/camera_left/depth/camera_info</depthImageInfoTopicName>
        <!-- <pointCloudTopicName>/camera_${name}/depth/points</pointCloudTopicName> -->
        <pointCloudTopicName>/cam3/point_cloud_left</pointCloudTopicName>
        <frameName>camera_optical_left</frameName>
        <pointCloudCutoff>0.1</pointCloudCutoff>
        <pointCloudCutoffMax>1.5</pointCloudCutoffMax>
        <distortionK1>0.0</distortionK1>
        <distortionK2>0.0</distortionK2>
        <distortionK3>0.0</distortionK3>
        <distortionT1>0.0</distortionT1>
        <distortionT2>0.0</distortionT2>
        <CxPrime>0</CxPrime>
        <Cx>0.0045</Cx>
        <Cy>0.0039</Cy>
        <focalLength>0</focalLength>
        <hackBaseline>0</hackBaseline>
      </plugin>
    </sensor>
  </gazebo>
  <joint name="camera_joint_right" type="fixed">
    <origin rpy="0 0.2618 -1.5707963267948966" xyz="-0.066 -0.082 -0.0176"/>
    <parent link="trunk"/>
    <child link="camera_right"/>
  </joint>
  <link name="camera_right">
    <collision>
      <origin rpy="0 0 0" xyz="0 0 0"/>
      <geometry>
        <box size=".001 .001 .001"/>
      </geometry>
    </collision>
    <visual>
      <origin rpy="0 0 0" xyz="0 0 0"/>
      <geometry>
        <mesh filename="package://go1_description/meshes/depthCamera.dae" scale="1 1 1"/>
      </geometry>
    </visual>
    <inertial>
      <mass value="1e-5"/>
      <origin rpy="0 0 0" xyz="0 0 0"/>
      <inertia ixx="1e-6" ixy="0" ixz="0" iyy="1e-6" iyz="0" izz="1e-6"/>
    </inertial>
  </link>
  <joint name="camera_optical_joint_right" type="fixed">
    <origin rpy="-1.5707963267948966 0 -1.5707963267948966" xyz="0 0 0"/>
    <parent link="camera_right"/>
    <child link="camera_optical_right"/>
  </joint>
  <link name="camera_optical_right">
        </link>
  <gazebo reference="camera_right">
    <!-- <material>Gazebo/Black</material> -->
    <sensor name="camera_right_camera" type="depth">
      <update_rate>16</update_rate>
      <camera>
        <horizontal_fov>2.094</horizontal_fov>
        <image>
          <width>928</width>
          <height>800</height>
          <format>B8G8R8</format>
        </image>
        <clip>
          <near>0.1</near>
          <far>5</far>
        </clip>
      </camera>
      <plugin filename="libgazebo_ros_openni_kinect.so" name="camera_right_controller">
        <baseline>0.025</baseline>
        <alwaysOn>true</alwaysOn>
        <updateRate>0.0</updateRate>
        <cameraName>camera_right_ir</cameraName>
        <imageTopicName>/camera_right/color/image_raw</imageTopicName>
        <cameraInfoTopicName>/camera_right/color/camera_info</cameraInfoTopicName>
        <depthImageTopicName>/camera_right/depth/image_raw</depthImageTopicName>
        <depthImageInfoTopicName>/camera_right/depth/camera_info</depthImageInfoTopicName>
        <!-- <pointCloudTopicName>/camera_${name}/depth/points</pointCloudTopicName> -->
        <pointCloudTopicName>/cam4/point_cloud_right</pointCloudTopicName>
        <frameName>camera_optical_right</frameName>
        <pointCloudCutoff>0.1</pointCloudCutoff>
        <pointCloudCutoffMax>1.5</pointCloudCutoffMax>
        <distortionK1>0.0</distortionK1>
        <distortionK2>0.0</distortionK2>
        <distortionK3>0.0</distortionK3>
        <distortionT1>0.0</distortionT1>
        <distortionT2>0.0</distortionT2>
        <CxPrime>0</CxPrime>
        <Cx>0.0045</Cx>
        <Cy>0.0039</Cy>
        <focalLength>0</focalLength>
        <hackBaseline>0</hackBaseline>
      </plugin>
    </sensor>
  </gazebo>
  <joint name="camera_joint_rearDown" type="fixed">
    <origin rpy="0 1.5707963267948966 0" xyz="-0.0825 -0.0125 -0.04365"/>
    <parent link="trunk"/>
    <child link="camera_rearDown"/>
  </joint>
  <link name="camera_rearDown">
    <collision>
      <origin rpy="0 0 0" xyz="0 0 0"/>
      <geometry>
        <box size=".001 .001 .001"/>
      </geometry>
    </collision>
    <visual>
      <origin rpy="0 0 0" xyz="0 0 0"/>
      <geometry>
        <mesh filename="package://go1_description/meshes/depthCamera.dae" scale="1 1 1"/>
      </geometry>
    </visual>
    <inertial>
      <mass value="1e-5"/>
      <origin rpy="0 0 0" xyz="0 0 0"/>
      <inertia ixx="1e-6" ixy="0" ixz="0" iyy="1e-6" iyz="0" izz="1e-6"/>
    </inertial>
  </link>
  <joint name="camera_optical_joint_rearDown" type="fixed">
    <origin rpy="-1.5707963267948966 0 -1.5707963267948966" xyz="0 0 0"/>
    <parent link="camera_rearDown"/>
    <child link="camera_optical_rearDown"/>
  </joint>
  <link name="camera_optical_rearDown">
        </link>
  <gazebo reference="camera_rearDown">
    <!-- <material>Gazebo/Black</material> -->
    <sensor name="camera_rearDown_camera" type="depth">
      <update_rate>16</update_rate>
      <camera>
        <horizontal_fov>2.094</horizontal_fov>
        <image>
          <width>928</width>
          <height>800</height>
          <format>B8G8R8</format>
        </image>
        <clip>
          <near>0.1</near>
          <far>5</far>
        </clip>
      </camera>
      <plugin filename="libgazebo_ros_openni_kinect.so" name="camera_rearDown_controller">
        <baseline>0.025</baseline>
        <alwaysOn>true</alwaysOn>
        <updateRate>0.0</updateRate>
        <cameraName>camera_rearDown_ir</cameraName>
        <imageTopicName>/camera_rearDown/color/image_raw</imageTopicName>
        <cameraInfoTopicName>/camera_rearDown/color/camera_info</cameraInfoTopicName>
        <depthImageTopicName>/camera_rearDown/depth/image_raw</depthImageTopicName>
        <depthImageInfoTopicName>/camera_rearDown/depth/camera_info</depthImageInfoTopicName>
        <!-- <pointCloudTopicName>/camera_${name}/depth/points</pointCloudTopicName> -->
        <pointCloudTopicName>/cam5/point_cloud_rearDown</pointCloudTopicName>
        <frameName>camera_optical_rearDown</frameName>
        <pointCloudCutoff>0.1</pointCloudCutoff>
        <pointCloudCutoffMax>1.5</pointCloudCutoffMax>
        <distortionK1>0.0</distortionK1>
        <distortionK2>0.0</distortionK2>
        <distortionK3>0.0</distortionK3>
        <distortionT1>0.0</distortionT1>
        <distortionT2>0.0</distortionT2>
        <CxPrime>0</CxPrime>
        <Cx>0.0045</Cx>
        <Cy>0.0039</Cy>
        <focalLength>0</focalLength>
        <hackBaseline>0</hackBaseline>
      </plugin>
    </sensor>
  </gazebo>
  <joint name="camera_laserscan_joint_left" type="fixed">
    <origin rpy="0 0.2618 0" xyz="0 0 0"/>
    <parent link="camera_left"/>
    <child link="camera_laserscan_link_left"/>
  </joint>
  <link name="camera_laserscan_link_left">
    </link>
  <joint name="camera_laserscan_joint_right" type="fixed">
    <origin rpy="0 0.2618 0" xyz="0 0 0"/>
    <parent link="camera_right"/>
    <child link="camera_laserscan_link_right"/>
  </joint>
  <link name="camera_laserscan_link_right">
    </link>
  <joint name="ultraSound_joint_left" type="fixed">
    <origin rpy="0 0.2618 1.5707963267948966" xyz="-0.0535  0.0826 0.00868"/>
    <parent link="trunk"/>
    <child link="ultraSound_left"/>
  </joint>
  <link name="ultraSound_left">
    <collision>
      <origin rpy="0 0 0" xyz="0 0 0"/>
      <geometry>
        <box size=".001 .001 .001"/>
      </geometry>
    </collision>
    <visual>
      <origin rpy="0 0 0" xyz="0 0 0"/>
      <geometry>
        <mesh filename="package://go1_description/meshes/ultraSound.dae" scale="1 1 1"/>
      </geometry>
      <material name="black"/>
    </visual>
    <inertial>
      <mass value="1e-5"/>
      <origin rpy="0 0 0" xyz="0 0 0"/>
      <inertia ixx="1e-6" ixy="0" ixz="0" iyy="1e-6" iyz="0" izz="1e-6"/>
    </inertial>
  </link>
  <joint name="ultraSound_joint_right" type="fixed">
    <origin rpy="0 0.2618 -1.5707963267948966" xyz="-0.0535 -0.0826 0.00868"/>
    <parent link="trunk"/>
    <child link="ultraSound_right"/>
  </joint>
  <link name="ultraSound_right">
    <collision>
      <origin rpy="0 0 0" xyz="0 0 0"/>
      <geometry>
        <box size=".001 .001 .001"/>
      </geometry>
    </collision>
    <visual>
      <origin rpy="0 0 0" xyz="0 0 0"/>
      <geometry>
        <mesh filename="package://go1_description/meshes/ultraSound.dae" scale="1 1 1"/>
      </geometry>
      <material name="black"/>
    </visual>
    <inertial>
      <mass value="1e-5"/>
      <origin rpy="0 0 0" xyz="0 0 0"/>
      <inertia ixx="1e-6" ixy="0" ixz="0" iyy="1e-6" iyz="0" izz="1e-6"/>
    </inertial>
  </link>
  <joint name="ultraSound_joint_face" type="fixed">
    <origin rpy="0 0 0" xyz="0.2747 0.0 -0.0088"/>
    <parent link="trunk"/>
    <child link="ultraSound_face"/>
  </joint>
  <link name="ultraSound_face">
    <collision>
      <origin rpy="0 0 0" xyz="0 0 0"/>
      <geometry>
        <box size=".001 .001 .001"/>
      </geometry>
    </collision>
    <visual>
      <origin rpy="0 0 0" xyz="0 0 0"/>
      <geometry>
        <mesh filename="package://go1_description/meshes/ultraSound.dae" scale="1 1 1"/>
      </geometry>
      <material name="black"/>
    </visual>
    <inertial>
      <mass value="1e-5"/>
      <origin rpy="0 0 0" xyz="0 0 0"/>
      <inertia ixx="1e-6" ixy="0" ixz="0" iyy="1e-6" iyz="0" izz="1e-6"/>
    </inertial>
  </link>

  <!-- <joint name="laser_main_joint" type="fixed">
    <origin rpy="0 1.57 0" xyz="0.178 -0.02 0.211"/>
    <parent link="trunk"/>
    <child link="rslidar_main"/>
  </joint>

  <link name="rslidar_main">
  </link>

  <joint name="laser_joint" type="fixed">
    <origin rpy="0 0 0.02" xyz="0 0 0"/>
    <parent link="rslidar_main"/>
    <child link="rslidar"/>
  </joint>

  <link name="rslidar">
    <collision>
      <origin rpy="-1.57 1.57 0" xyz="0.0 -0.05 0.0"/>
      <geometry>
        <cylinder length="0.1" radius="0.05"/>
      </geometry>
    </collision>
    <visual>
      <origin rpy="-1.57 0 0.357" xyz="0.0 0.02 0.0"/>
      <geometry>
        <mesh filename="package://go1_description/meshes/bpearl.dae" scale="1 1 1"/>
      </geometry>
      <material name="black"/>
    </visual>
    <inertial>
      <mass value="1e-5"/>
      <origin rpy="0 0 0" xyz="0.0 0 0.0"/>
      <inertia ixx="1e-6" ixy="0" ixz="0" iyy="1e-6" iyz="0" izz="1e-6"/>
    </inertial>
  </link> -->

  <joint name="hesai_main_joint" type="fixed">
    <origin rpy="0 1.57 0" xyz="0.168 -0.02 0.211"/>
    <parent link="trunk"/>
    <child link="hesai"/>
  </joint>

  <link name="hesai">
  </link>

  <joint name="hesai_joint" type="fixed">
    <origin rpy="0 0 0.02" xyz="0 0 0"/>
    <parent link="hesai"/>
    <child link="hesai_jt128"/>
  </joint>

  <link name="hesai_jt128">
    <collision>
      <origin rpy="0.0 0.0 0.0" xyz="0.0 0.02 0.035"/>
      <geometry>
        <cylinder length="0.08" radius="0.035"/>
      </geometry>
    </collision>
    <visual>
      <!-- <origin rpy="0 -0.357 0" xyz="0.0 0 0.0"/> -->
      <origin rpy="0.0 0.0 -1.57" xyz="0.0 0.02 0.0"/>
      <geometry>
        <mesh filename="package://go1_description/meshes/hesai-jt128.dae" scale="0.001 0.001 0.001"/>
      </geometry>
      <material name="black"/>
    </visual>
    <inertial>
      <mass value="1e-5"/>
      <origin rpy="0 0 0" xyz="0.0 0 0.0"/>
      <inertia ixx="1e-6" ixy="0" ixz="0" iyy="1e-6" iyz="0" izz="1e-6"/>
    </inertial>
  </link>

  <joint name="realsense_joint" type="fixed">
    <!-- <origin rpy="-1.57 0 1.57" xyz="0.161909 0 0.118288"/> -->
    <origin rpy="0 0 0" xyz="0.177033 0 0.129929"/>
    <parent link="trunk"/>
    <child link="camera_link"/>
  </joint>

  <link name="camera_link">
    <collision>
      <origin rpy="0 0 1.57" xyz="-0.01 0.0 0.0"/>
      <geometry>
        <!-- <cylinder length="0.05" radius="0.05"/> -->
        <box size="0.09 0.03 0.035"/>
      </geometry>
    </collision>
    <visual>
      <origin rpy="-1.57 0 1.57" xyz="0.0 0 0.0"/>
      <geometry>
        <mesh filename="package://go1_description/meshes/realsense_D435i.dae" scale="1000 1000 1000"/>
      </geometry>
      <material name="black"/>
    </visual>
    <inertial>
      <mass value="1e-5"/>
      <origin rpy="0 0 0" xyz="0.0 0 0.0"/>
      <inertia ixx="1e-6" ixy="0" ixz="0" iyy="1e-6" iyz="0" izz="1e-6"/>
    </inertial>
  </link>
  <joint name="support_joint" type="fixed">
    <origin rpy="0 0 0" xyz="0.140302 0 0.056084"/>
    <parent link="trunk"/>
    <child link="support_link"/>
  </joint>
  <link name="support_link">
    <collision>
      <origin rpy="0 0 0" xyz="-0.02 0.0 0.09"/>
      <geometry>
        <cylinder length="0.2" radius="0.04"/>
      </geometry>
    </collision>
    <visual>
      <origin rpy="0 0 3.14" xyz="0.0 0 0.0"/>
      <geometry>
        <mesh filename="package://go1_description/meshes/Suporte_Lidar_V005.dae" scale="1 1 1"/>
      </geometry>
      <material name="black"/>
    </visual>
    <inertial>
      <mass value="1e-5"/>
      <origin rpy="0 0 0" xyz="0.0 0 0.0"/>
      <inertia ixx="1e-6" ixy="0" ixz="0" iyy="1e-6" iyz="0" izz="1e-6"/>
    </inertial>
  </link>
  <joint name="rtk_joint" type="fixed">
    <origin rpy="-1.57 0 -1.57" xyz="-0.085809 -0.065877 0.082355"/>
    <parent link="trunk"/>
    <child link="gps"/>
  </joint>
  <link name="gps">
    <collision>
      <origin rpy="0 0 0" xyz="-0.065 -0.045 -0.05"/>
      <geometry>
        <box size="0.13 0.1 0.1"/>
      </geometry>
    </collision>
    <visual>
      <origin rpy="0 0 3.14" xyz="0.0 0 0.0"/>
      <geometry>
        <mesh filename="package://go1_description/meshes/RTK-Antenna-Support-Base.dae" scale="1000 1000 1000"/>
      </geometry>
      <material name="black"/>
    </visual>
    <inertial>
      <mass value="1e-5"/>
      <origin rpy="0 0 0" xyz="0.0 0 0.0"/>
      <inertia ixx="1e-6" ixy="0" ixz="0" iyy="1e-6" iyz="0" izz="1e-6"/>
    </inertial>
  </link>
  <joint name="xsens_joint" type="fixed">
    <origin rpy="0 0 1.57" xyz="0.114817 -0.008000 0.269"/>
    <parent link="trunk"/>
    <child link="imu"/>
  </joint>
  <link name="imu">
    <collision>
      <origin rpy="0 0 0" xyz="0.01 0 0.0"/>
      <geometry>
        <box size="0.05 0.07 0.05"/>
      </geometry>
    </collision>
    <visual>
      <origin rpy="0 0 3.14" xyz="0.0 0 0.0"/>
      <geometry>
        <mesh filename="package://go1_description/meshes/IMU_Mti-6R.dae" scale="1 1 1"/>
      </geometry>
      <material name="black"/>
    </visual>
    <inertial>
      <mass value="1e-5"/>
      <origin rpy="0 0 0" xyz="0.0 0 0.0"/>
      <inertia ixx="1e-6" ixy="0" ixz="0" iyy="1e-6" iyz="0" izz="1e-6"/>
    </inertial>
  </link>
  <joint name="mag_joint" type="fixed">
    <origin rpy="3.14 0 1.57" xyz="-0.13 -0.0465 0.129"/>
    <parent link="trunk"/>
    <child link="mag"/>
  </joint>
  <link name="mag">
    <collision>
      <origin rpy="0 0 0" xyz="0.01 0 0.0"/>
      <geometry>
        <box size="0.05 0.07 0.05"/>
      </geometry>
    </collision>
    <visual>
      <origin rpy="0 0 3.14" xyz="0.0 0 0.0"/>
      <geometry>
        <mesh filename="package://go1_description/meshes/rm3100.dae" scale="1 1 1"/>
      </geometry>
      <material name="black"/>
    </visual>
    <inertial>
      <mass value="1e-5"/>
      <origin rpy="0 0 0" xyz="0.0 0 0.0"/>
      <inertia ixx="1e-6" ixy="0" ixz="0" iyy="1e-6" iyz="0" izz="1e-6"/>
    </inertial>
  </link>

  <joint name="nvidia_joint" type="fixed">
    <origin rpy="0 0 0" xyz="-0.05 -0.05 0.12"/>
    <parent link="trunk"/>
    <child link="nvidia"/>
  </joint>
  <link name="nvidia">
    <collision>
      <origin rpy="0 0 0" xyz="0.05 0.05 0.01"/>
      <geometry>
        <box size="0.1 0.1 0.07"/>
      </geometry>
    </collision>
    <visual>
      <origin rpy="0 0 0" xyz="0.0 0 0.0"/>
      <geometry>
        <mesh filename="package://go1_description/meshes/nvidia-agx-orin-dev-kit.dae" scale="1 1 1"/>
      </geometry>
      <material name="black"/>
    </visual>
    <inertial>
      <mass value="1e-5"/>
      <origin rpy="0 0 0" xyz="0.0 0 0.0"/>
      <inertia ixx="1e-6" ixy="0" ixz="0" iyy="1e-6" iyz="0" izz="1e-6"/>
    </inertial>
  </link> 

  <!-- <gazebo reference="rslidar">
    <material>Gazebo/Black</material>
    <gravity>true</gravity>
    <sensor name="rslidar" type="ray">
      <pose>0.178 0 0.211 -1.57 1.57 0</pose>
      <visualize>false</visualize>
      <update_rate>40</update_rate>
      <ray>
        <scan>
          <horizontal>
            <samples>360</samples>
            <resolution>1</resolution>
            <min_angle>-3.141592653589793</min_angle>
            <max_angle>3.141592653589793</max_angle>
          </horizontal>
        </scan>
        <range>
          <min>0.2</min>
          <max>40</max>
          <resolution>0.025</resolution>
        </range>
        <noise>
          <type>gaussian</type>
          <mean>0.0</mean>
          <stddev>0.0</stddev>
        </noise>
      </ray>
      <plugin filename="libgazebo_ros_laser.so" name="laser_controller">
        <robotNamespace/>
        <topicName>/rslidar_points</topicName>
        <frameName>rslidar</frameName>
      </plugin>
    </sensor>
  </gazebo> -->

  <gazebo reference="hesai_jt128">
    <material>Gazebo/Black</material>
    <gravity>true</gravity>
    <sensor name="rslidar" type="ray">
      <pose>0.168 -0.02 0.211 0 1.57 0</pose>
      <visualize>false</visualize>
      <update_rate>40</update_rate>
      <ray>
        <scan>
          <horizontal>
            <samples>360</samples>
            <resolution>1</resolution>
            <min_angle>-3.141592653589793</min_angle>
            <max_angle>3.141592653589793</max_angle>
          </horizontal>
        </scan>
        <range>
          <min>0.2</min>
          <max>40</max>
          <resolution>0.025</resolution>
        </range>
        <noise>
          <type>gaussian</type>
          <mean>0.0</mean>
          <stddev>0.0</stddev>
        </noise>
      </ray>
      <plugin filename="libgazebo_ros_laser.so" name="laser_controller">
        <robotNamespace/>
        <topicName>/hesai_points</topicName>
        <frameName>hesai_jt128</frameName>
      </plugin>
    </sensor>
  </gazebo>
</robot>
